<?xml version="1.0"?>

<robot name="m100" xmlns:xacro="http://wiki.ros.org/xacro">

  <xacro:property name="pi" value="3.1415926535897931" />



     <link name="base">
       <visual>
     <origin xyz="0 0 0" rpy="0 0 0" />
         <geometry>
            <box size=".2 .2 0.04"/>
         </geometry>
       </visual>
       <collision>
          <origin xyz="0 0 0" rpy="0 0 0" />
          <geometry>
            <box size="0.2 0.2 .04"/>
          </geometry>
        </collision>
        <inertial>
           <mass value="0.2"/>
           <inertia ixx="1.0" ixy="0.0" ixz="0.0" iyy="1.0" iyz="0.0" izz="1.0"/>
         </inertial>
     </link>

     <link name="link_01">
       <visual>
     <origin xyz="0 0 0" rpy="0 3.14 0" />
         <geometry>
            <cylinder length="0.07" radius="0.03"/>
         </geometry>
       </visual>
       <collision>
          <origin xyz="0 0 0" rpy="0 3.14 0" />
          <geometry>
            <cylinder length="0.07" radius="0.03"/>
          </geometry>
        </collision>
        <inertial>
           <mass value="0.0842"/>
           <inertia ixx="1.0" ixy="0.0" ixz="0.0" iyy="1.0" iyz="0.0" izz="1.0"/>
         </inertial>
     </link>

    <link name="link_02">
       <visual>
     <origin xyz="0 0 .1" rpy="0 0 0" />
         <geometry>
            <cylinder length="0.2" radius="0.02"/>
         </geometry>
       </visual>
       <collision>
          <origin xyz="0 0 .1" rpy="0 0 0" />
          <geometry>
            <cylinder length="0.2" radius="0.02"/>
          </geometry>
        </collision>
        <inertial>
           <mass value="0.0464"/>
           <inertia ixx="1.0" ixy="0.0" ixz="0.0" iyy="1.0" iyz="0.0" izz="1.0"/>
         </inertial>
    </link>

    <link name="link_03">
       <visual>
     <origin xyz="0 0 .0875" rpy="0 0 0" />
         <geometry>
            <cylinder length="0.175" radius="0.02"/>
         </geometry>
       </visual>
       <collision>
          <origin xyz="0 0 .0875" rpy="0 0 0" />
          <geometry>
            <cylinder length="0.175" radius="0.02"/>
          </geometry>
        </collision>
        <inertial>
           <mass value="0.0464"/>
           <inertia ixx="1.0" ixy="0.0" ixz="0.0" iyy="1.0" iyz="0.0" izz="1.0"/>
         </inertial>
     </link>


     <joint name="joint0" type="revolute">
       <axis xyz="0 0 1" />
       <limit effort="1000" lower="-3.14" upper="3.14" velocity=".5" />
       <origin rpy="0 0 0" xyz="0 0 .035" />
       <parent link="base"/>
       <child link="link_01"/>
     </joint>

     <joint name="joint1" type="revolute">
       <axis xyz="0 1 0" />
       <limit effort="1000" lower="-1.57" upper="0" velocity=".5" />
       <origin rpy="0 1.57 0" xyz="0 0 0" />
       <parent link="link_01"/>
       <child link="link_02"/>
     </joint>
     <joint name="joint2" type="revolute">
       <axis xyz="0 1 0" />
       <limit effort="1000" lower="0" upper="1.57" velocity=".5" />
       <origin rpy="0 -3.14 0" xyz="0 0 0.2" />
       <parent link="link_02"/>
       <child link="link_03"/>
     </joint>

     <gazebo reference="base_link">
       <material>Gazebo/Blue</material>
       <turnGravityOff>false</turnGravityOff>
     </gazebo>


</robot>

